Workbook

Sheet OrderList
A1: Order ID | B1: Order Date | C1: Origin Port | D1: Carrier | E1: TPT | F1: Service Level | G1: Ship ahead day count | H1: Ship Late Day count | I1: Customer | J1: Product ID | K1: Plant Code | L1: Destination Port | M1: Unit quantity | N1: Weight
A2: 1.4472964e+09 | B2: 41420 | C2: PORT09 | D2: V44_3 | E2: 1 | F2: CRF | G2: 3 | H2: 0 | I2: V55555_53 | J2: 1700106 | K2: PLANT16 | L2: PORT09 | M2: 808 | N2: 14.3
A3: 1.447158e+09 | B3: 41420 | C3: PORT09 | D3: V44_3 | E3: 1 | F3: CRF | G3: 3 | H3: 0 | I3: V55555_53 | J3: 1700106 | K3: PLANT16 | L3: PORT09 | M3: 3188 | N3: 87.94
A4: 1.4471389e+09 | B4: 41420 | C4: PORT09 | D4: V44_3 | E4: 1 | F4: CRF | G4: 3 | H4: 0 | I4: V55555_53 | J4: 1700106 | K4: PLANT16 | L4: PORT09 | M4: 2331 | N4: 61.2
A5: 1.4473635e+09 | B5: 41420 | C5: PORT09 | D5: V44_3 | E5: 1 | F5: CRF | G5: 3 | H5: 0 | I5: V55555_53 | J5: 1700106 | K5: PLANT16 | L5: PORT09 | M5: 847 | N5: 16.16
A6: 1.447364e+09 | B6: 41420 | C6: PORT09 | D6: V44_3 | E6: 1 | F6: CRF | G6: 3 | H6: 0 | I6: V55555_53 | J6: 1700106 | K6: PLANT16 | L6: PORT09 | M6: 2163 | N6: 52.34
A7: 1.4473514e+09 | B7: 41420 | C7: PORT09 | D7: V44_3 | E7: 1 | F7: CRF | G7: 3 | H7: 0 | I7: V55555_53 | J7: 1700106 | K7: PLANT16 | L7: PORT09 | M7: 3332 | N7: 92.8
A8: 1.4473202e+09 | B8: 41420 | C8: PORT09 | D8: V44_3 | E8: 1 | F8: CRF | G8: 3 | H8: 0 | I8: V55555_53 | J8: 1700106 | K8: PLANT16 | L8: PORT09 | M8: 1782 | N8: 46.9
A9: 1.447158e+09 | B9: 41420 | C9: PORT09 | D9: V44_3 | E9: 1 | F9: CRF | G9: 3 | H9: 0 | I9: V55555_53 | J9: 1700106 | K9: PLANT16 | L9: PORT09 | M9: 427 | N9: 2.86
A10: 1.4472193e+09 | B10: 41420 | C10: PORT09 | D10: V44_3 | E10: 1 | F10: CRF | G10: 3 | H10: 0 | I10: V55555_53 | J10: 1700106 | K10: PLANT16 | L10: PORT09 | M10: 1291 | N10: 26.6
A11: 1.4473984e+09 | B11: 41420 | C11: PORT09 | D11: V44_3 | E11: 1 | F11: CRF | G11: 3 | H11: 0 | I11: V55555_53 | J11: 1700106 | K11: PLANT16 | L11: PORT09 | M11: 2294 | N11: 62.2
A12: 1.4473817e+09 | B12: 41420 | C12: PORT09 | D12: V44_3 | E12: 1 | F12: CRF | G12: 3 | H12: 0 | I12: V55555_53 | J12: 1700106 | K12: PLANT16 | L12: PORT09 | M12: 2766 | N12: 75.5
A13: 1.4471708e+09 | B13: 41420 | C13: PORT09 | D13: V44_3 | E13: 1 | F13: CRF | G13: 3 | H13: 0 | I13: V55555_53 | J13: 1700106 | K13: PLANT16 | L13: PORT09 | M13: 798 | N13: 14.3
... A9216: 1.4473281e+09 | B9216: 41420 | C9216: PORT04 | D9216: V444_1 | E9216: 1 | F9216: DTD | G9216: 5 | H9216: 0 | I9216: V55555555555555_8 | J9216: 1683424 | K9216: PLANT03 | L9216: PORT09 | M9216: 317 | N9216: 1.96

Sheet Order_Analysis
A1: Row Labels | B1: Sum of Unit quantity | C1: Count of Order ID | E1: Total Demand (Units)
A2: 1684862 | B2: 3470409 | C2: 16 | E2: =SUM(OrderList!M2:M9216) -> 29513315
A3: 1676592 | B3: 1119252 | C3: 22
A4: 1700569 | B4: 904493 | C4: 3
A5: 1664051 | B5: 873011 | C5: 37 | E5: Row Labels | F5: Sum of Unit quantity | G5: Count of Order ID | K5: Count of Plant Code | M5: Number of Supplying Plants | N5: Number of Products
A6: 1667927 | B6: 814076 | C6: 20 | E6: PLANT03 | F6: 28611617 | G6: 8541 | J6: 1687191 | K6: 5 | M6: 1 | N6: =COUNTIF($K$6:$K$777,M6) -> 503
A7: 1700140 | B7: 811381 | C7: 17 | E7: PLANT08 | F7: 277008 | G7: 102 | J7: 1684646 | K7: 5 | M7: 2 | N7: =COUNTIF($K$6:$K$777,M7) -> 141
A8: 1683560 | B8: 772283 | C8: 30 | E8: PLANT16 | F8: 245133 | G8: 173 | J8: 1684725 | K8: 5 | M8: 3 | N8: =COUNTIF($K$6:$K$777,M8) -> 43
A9: 1666524 | B9: 670437 | C9: 19 | E9: PLANT09 | F9: 223830 | G9: 12 | J9: 1684722 | K9: 5 | M9: 4 | N9: =COUNTIF($K$6:$K$777,M9) -> 71
A10: 1700130 | B10: 658352 | C10: 9 | E10: PLANT12 | F10: 112000 | G10: 300 | J10: 1680742 | K10: 5 | M10: 5 | N10: =COUNTIF($K$6:$K$777,M10) -> 14
A11: 1700143 | B11: 654556 | C11: 10 | E11: PLANT13 | F11: 43379 | G11: 86 | J11: 1684644 | K11: 5
A12: 1661099 | B12: 560687 | C12: 6 | E12: PLANT04 | F12: 348 | G12: 1 | J12: 1683354 | K12: 5
A13: 1671426 | B13: 523433 | C13: 36 | E13: Grand Total | F13: 29513315 | G13: 9215 | J13: 1684649 | K13: 5
A14: 1684560 | B14: 509739 | C14: 52 | J14: 1685107 | K14: 5
A15: 1700142 | B15: 453026 | C15: 11 | E15: =MIN(OrderList!B2:B9216) -> 41420 | J15: 1684724 | K15: 5
A16: 1678000 | B16: 432782 | C16: 18 | E16: =MAX(OrderList!B2:B9216) -> 41420 | J16: 1683760 | K16: 5
A17: 1700139 | B17: 432338 | C17: 12 | J17: 1684728 | K17: 5
A18: 1693230 | B18: 366911 | C18: 11 | E18: =AVERAGE(OrderList!M2:M9216) -> 3202.7472 | J18: 1683769 | K18: 5
A19: 1664067 | B19: 365628 | C19: 15 | E19: =MAX(OrderList!M2:M9216) -> 561847 | J19: 1684743 | K19: 5
A20: 1699540 | B20: 341263 | C20: 25 | J20: 1689547 | K20: 4
A21: 1674598 | B21: 339161 | C21: 23 | J21: 1690627 | K21: 4
A22: 1685028 | B22: 334332 | C22: 15 | J22: 1689780 | K22: 4
A23: 1700137 | B23: 307136 | C23: 9 | J23: 1689784 | K23: 4
A24: 1699574 | B24: 302349 | C24: 12 | J24: 1688285 | K24: 4
A25: 1655818 | B25: 298241 | C25: 86 | J25: 1691700 | K25: 4
A26: 1651299 | B26: 290185 | C26: 63 | J26: 1688288 | K26: 4
A27: 1677878 | B27: 287598 | C27: 140 | J27: 1689549 | K27: 4
A28: 1677891 | B28: 268576 | C28: 86 | J28: 1688290 | K28: 4
A29: 1682210 | B29: 254751 | C29: 8 | J29: 1689782 | K29: 4
A30: 1700138 | B30: 242995 | C30: 5 | J30: 1688292 | K30: 4
A31: 1699792 | B31: 242801 | C31: 10 | J31: 1690616 | K31: 4
... A773: 1685321 | B773: 239 | C773: 1 | J773: 1691766 | K773: 1
A774: Grand Total | B774: 29513315 | C774: 9215 | J774: 1686001 | K774: 1
J775: 1691768 | K775: 1
J776: 1686002 | K776: 1
J777: 1691770 | K777: 1
J778: 1689553 | K778: 1
J779: 1691772 | K779: 1
J780: 1689554 | K780: 1
J781: 1691774 | K781: 1
...

Sheet Capacity_Analysis
A1: Row Labels | B1: Sum of Daily Capacity
A2: PLANT01 | B2: 1070
A3: PLANT02 | B3: 138
A4: PLANT03 | B4: 1013
A5: PLANT04 | B5: 554
A6: PLANT05 | B6: 385
A7: PLANT06 | B7: 49
A8: PLANT07 | B8: 265
A9: PLANT08 | B9: 14
A10: PLANT09 | B10: 11
A11: PLANT10 | B11: 118
A12: PLANT11 | B12: 332
A13: PLANT12 | B13: 209
... A21: Grand Total | B21: 5791

Sheet Cost_Analysis
A1: Row Labels | B1: Sum of Cost/unit
A2: PLANT01 | B2: 0.56697618
A3: PLANT02 | B3: 0.47750352
A4: PLANT03 | B4: 0.51750189
A5: PLANT04 | B5: 0.4285033
A6: PLANT05 | B6: 0.48814438
A7: PLANT06 | B7: 0.5540881
A8: PLANT07 | B8: 0.37142394
A9: PLANT08 | B9: 0.5228573
A10: PLANT09 | B10: 0.4650711
A11: PLANT10 | B11: 0.4935819
A12: PLANT11 | B12: 0.55524729
A13: PLANT12 | B13: 0.77313179
... A21: Grand Total | B21: 13.757901

Sheet FreightRates
A1: Carrier | B1: orig_port_cd | C1: dest_port_cd | D1: minm_wgh_qty | E1: max_wgh_qty | F1: svc_cd | G1: minimum cost | H1: rate | I1: mode_dsc | J1: tpt_day_cnt | K1: Carrier type
A2: V444_6 | B2: PORT08 | C2: PORT09 | D2: 250 | E2: 499.99 | F2: DTD | G2: 43.2272 | H2: 0.7132 | I2: AIR | J2: 2 | K2: V88888888_0
A3: V444_6 | B3: PORT08 | C3: PORT09 | D3: 65 | E3: 69.99 | F3: DTD | G3: 43.2272 | H3: 0.7512 | I3: AIR | J3: 2 | K3: V88888888_0
A4: V444_6 | B4: PORT08 | C4: PORT09 | D4: 60 | E4: 64.99 | F4: DTD | G4: 43.2272 | H4: 0.7892 | I4: AIR | J4: 2 | K4: V88888888_0
A5: V444_6 | B5: PORT08 | C5: PORT09 | D5: 50 | E5: 54.99 | F5: DTD | G5: 43.2272 | H5: 0.8272 | I5: AIR | J5: 2 | K5: V88888888_0
A6: V444_6 | B6: PORT08 | C6: PORT09 | D6: 35 | E6: 39.99 | F6: DTD | G6: 43.2272 | H6: 1.0552 | I6: AIR | J6: 2 | K6: V88888888_0
A7: V444_6 | B7: PORT08 | C7: PORT09 | D7: 100 | E7: 249.99 | F7: DTD | G7: 43.2272 | H7: 0.7132 | I7: AIR | J7: 2 | K7: V88888888_0
A8: V444_6 | B8: PORT08 | C8: PORT09 | D8: 500 | E8: 1999.99 | F8: DTD | G8: 43.2272 | H8: 0.6752 | I8: AIR | J8: 2 | K8: V88888888_0
A9: V444_6 | B9: PORT08 | C9: PORT09 | D9: 55 | E9: 59.99 | F9: DTD | G9: 43.2272 | H9: 0.8272 | I9: AIR | J9: 2 | K9: V88888888_0
A10: V444_6 | B10: PORT08 | C10: PORT09 | D10: 25 | E10: 29.99 | F10: DTD | G10: 43.2272 | H10: 1.2452 | I10: AIR | J10: 2 | K10: V88888888_0
A11: V444_6 | B11: PORT08 | C11: PORT09 | D11: 30 | E11: 34.99 | F11: DTD | G11: 43.2272 | H11: 1.1312 | I11: AIR | J11: 2 | K11: V88888888_0
A12: V444_6 | B12: PORT08 | C12: PORT09 | D12: 70 | E12: 99.99 | F12: DTD | G12: 43.2272 | H12: 0.7512 | I12: AIR | J12: 2 | K12: V88888888_0
A13: V444_6 | B13: PORT08 | C13: PORT09 | D13: 10 | E13: 14.99 | F13: DTD | G13: 43.2272 | H13: 1.8272 | I13: AIR | J13: 2 | K13: V88888888_0
... A1541: V444_8 | B1541: PORT03 | C1541: PORT09 | D1541: 100 | E1541: 249.99 | F1541: DTD | G1541: 29.3392 | H1541: 0.4116 | I1541: AIR | J1541: 0 | K1541: V88888888_0

Sheet Freight_Analysis
A1: Row Labels | B1: Min of minimum cost | C1: Min of rate | D1: Max of rate
A2: PORT02 | B2: 1.43 | C2: 0.0484 | D2: 7.0608
A3: PORT03 | B3: 19.3644 | C3: 0.1156 | D3: 128.0272
A4: PORT04 | B4: 1.202 | C4: 0.0424 | D4: 7.664
A5: PORT05 | B5: 1.5584 | C5: 0.072 | D5: 12.0728
A6: PORT06 | B6: 1.3352 | C6: 0.074 | D6: 7.1628
A7: PORT07 | B7: 9.6272 | C7: 0.1448 | D7: 0.2772
A8: PORT08 | B8: 19.0272 | C8: 0.1016 | D8: 1.8272
A9: PORT09 | B9: 17.6888 | C9: 0.0332 | D9: 21.2784
A10: PORT10 | B10: 1.4024 | C10: 0.0964 | D10: 18.963054
A11: PORT11 | B11: 7.8272 | C11: 0.0684 | D11: 0.3448
A12: Grand Total | B12: 1.202 | C12: 0.0332 | D12: 128.0272

Sheet Order_Freight_Analysis
A1: Order ID | B1: Origin Port | C1: Carrier | D1: Service Level | E1: Destination Port | F1: Plant Code | G1: Product ID | H1: Unit Quantity | I1: Weight | J1: Matched Rate | K1: Minimum Freight Cost | L1: Transit Days | M1: Transport Mode | N1: Match Status | O1: Candidate Matches | P1: Carrier Match Summary | Q1: Route + Carrier Matches | R1: Orders with Route + Carrier Match | S1: Total Route + Carrier Matches | T1: Full Match Count | U1: Orders with Full Match
A2: =OrderList!A2 -> 1.4472964e+09 | B2: =OrderList!C2 -> PORT09 | C2: =OrderList!D2 -> V44_3 | D2: =OrderList!F2 -> CRF | E2: =OrderList!L2 -> PORT09 | F2: =OrderList!K2 -> PLANT16 | G2: =OrderList!J2 -> 1700106 | H2: =OrderList!M2 -> 808 | I2: =OrderList!N2 -> 14.3 | O2: =COUNTIF(FreightRates!$A$2:$A$1541,C2) -> 0 | P2: =COUNTIF(O2:O9216,">0") -> 8361 | Q2: =COUNTIFS(FreightRates!$A$2:$A$1541,C2,FreightRates!$B$2:$B$1541,B2,FreightRates!$C$2:$C$1541,E2) -> 0 | R2: =COUNTIF(Q2:Q9216,">0") -> 8361 | S2: =SUMPRODUCT(--(Q2:Q9216>0)) -> 8361 | T2: =COUNTIFS(FreightRates!$A$2:$A$1541,C2,FreightRates!$B$2:$B$1541,B2,FreightRates!$C$2:$C$1541,E2,FreightRates!$F$2:$F$1541,D2,FreightRates!$D$2:$D$1541,"<="&I2,FreightRates!$E$2:$E$1541,">="&I2) -> 0 | U2: =COUNTIF(T2:T9216,">0") -> 6991
A3: =OrderList!A3 -> 1.447158e+09 | B3: =OrderList!C3 -> PORT09 | C3: =OrderList!D3 -> V44_3 | D3: =OrderList!F3 -> CRF | E3: =OrderList!L3 -> PORT09 | F3: =OrderList!K3 -> PLANT16 | G3: =OrderList!J3 -> 1700106 | H3: =OrderList!M3 -> 3188 | I3: =OrderList!N3 -> 87.94 | O3: =COUNTIF(FreightRates!$A$2:$A$1541,C3) -> 0 | Q3: =COUNTIFS(FreightRates!$A$2:$A$1541,C3,FreightRates!$B$2:$B$1541,B3,FreightRates!$C$2:$C$1541,E3) -> 0 | T3: =COUNTIFS(FreightRates!$A$2:$A$1541,C3,FreightRates!$B$2:$B$1541,B3,FreightRates!$C$2:$C$1541,E3,FreightRates!$F$2:$F$1541,D3,FreightRates!$D$2:$D$1541,"<="&I3,FreightRates!$E$2:$E$1541,">="&I3) -> 0
A4: =OrderList!A4 -> 1.4471389e+09 | B4: =OrderList!C4 -> PORT09 | C4: =OrderList!D4 -> V44_3 | D4: =OrderList!F4 -> CRF | E4: =OrderList!L4 -> PORT09 | F4: =OrderList!K4 -> PLANT16 | G4: =OrderList!J4 -> 1700106 | H4: =OrderList!M4 -> 2331 | I4: =OrderList!N4 -> 61.2 | O4: =COUNTIF(FreightRates!$A$2:$A$1541,C4) -> 0 | Q4: =COUNTIFS(FreightRates!$A$2:$A$1541,C4,FreightRates!$B$2:$B$1541,B4,FreightRates!$C$2:$C$1541,E4) -> 0 | T4: =COUNTIFS(FreightRates!$A$2:$A$1541,C4,FreightRates!$B$2:$B$1541,B4,FreightRates!$C$2:$C$1541,E4,FreightRates!$F$2:$F$1541,D4,FreightRates!$D$2:$D$1541,"<="&I4,FreightRates!$E$2:$E$1541,">="&I4) -> 0
A5: =OrderList!A5 -> 1.4473635e+09 | B5: =OrderList!C5 -> PORT09 | C5: =OrderList!D5 -> V44_3 | D5: =OrderList!F5 -> CRF | E5: =OrderList!L5 -> PORT09 | F5: =OrderList!K5 -> PLANT16 | G5: =OrderList!J5 -> 1700106 | H5: =OrderList!M5 -> 847 | I5: =OrderList!N5 -> 16.16 | O5: =COUNTIF(FreightRates!$A$2:$A$1541,C5) -> 0 | Q5: =COUNTIFS(FreightRates!$A$2:$A$1541,C5,FreightRates!$B$2:$B$1541,B5,FreightRates!$C$2:$C$1541,E5) -> 0 | T5: =COUNTIFS(FreightRates!$A$2:$A$1541,C5,FreightRates!$B$2:$B$1541,B5,FreightRates!$C$2:$C$1541,E5,FreightRates!$F$2:$F$1541,D5,FreightRates!$D$2:$D$1541,"<="&I5,FreightRates!$E$2:$E$1541,">="&I5) -> 0
A6: =OrderList!A6 -> 1.447364e+09 | B6: =OrderList!C6 -> PORT09 | C6: =OrderList!D6 -> V44_3 | D6: =OrderList!F6 -> CRF | E6: =OrderList!L6 -> PORT09 | F6: =OrderList!K6 -> PLANT16 | G6: =OrderList!J6 -> 1700106 | H6: =OrderList!M6 -> 2163 | I6: =OrderList!N6 -> 52.34 | O6: =COUNTIF(FreightRates!$A$2:$A$1541,C6) -> 0 | Q6: =COUNTIFS(FreightRates!$A$2:$A$1541,C6,FreightRates!$B$2:$B$1541,B6,FreightRates!$C$2:$C$1541,E6) -> 0 | T6: =COUNTIFS(FreightRates!$A$2:$A$1541,C6,FreightRates!$B$2:$B$1541,B6,FreightRates!$C$2:$C$1541,E6,FreightRates!$F$2:$F$1541,D6,FreightRates!$D$2:$D$1541,"<="&I6,FreightRates!$E$2:$E$1541,">="&I6) -> 0
A7: =OrderList!A7 -> 1.4473514e+09 | B7: =OrderList!C7 -> PORT09 | C7: =OrderList!D7 -> V44_3 | D7: =OrderList!F7 -> CRF | E7: =OrderList!L7 -> PORT09 | F7: =OrderList!K7 -> PLANT16 | G7: =OrderList!J7 -> 1700106 | H7: =OrderList!M7 -> 3332 | I7: =OrderList!N7 -> 92.8 | O7: =COUNTIF(FreightRates!$A$2:$A$1541,C7) -> 0 | Q7: =COUNTIFS(FreightRates!$A$2:$A$1541,C7,FreightRates!$B$2:$B$1541,B7,FreightRates!$C$2:$C$1541,E7) -> 0 | T7: =COUNTIFS(FreightRates!$A$2:$A$1541,C7,FreightRates!$B$2:$B$1541,B7,FreightRates!$C$2:$C$1541,E7,FreightRates!$F$2:$F$1541,D7,FreightRates!$D$2:$D$1541,"<="&I7,FreightRates!$E$2:$E$1541,">="&I7) -> 0
A8: =OrderList!A8 -> 1.4473202e+09 | B8: =OrderList!C8 -> PORT09 | C8: =OrderList!D8 -> V44_3 | D8: =OrderList!F8 -> CRF | E8: =OrderList!L8 -> PORT09 | F8: =OrderList!K8 -> PLANT16 | G8: =OrderList!J8 -> 1700106 | H8: =OrderList!M8 -> 1782 | I8: =OrderList!N8 -> 46.9 | O8: =COUNTIF(FreightRates!$A$2:$A$1541,C8) -> 0 | Q8: =COUNTIFS(FreightRates!$A$2:$A$1541,C8,FreightRates!$B$2:$B$1541,B8,FreightRates!$C$2:$C$1541,E8) -> 0 | T8: =COUNTIFS(FreightRates!$A$2:$A$1541,C8,FreightRates!$B$2:$B$1541,B8,FreightRates!$C$2:$C$1541,E8,FreightRates!$F$2:$F$1541,D8,FreightRates!$D$2:$D$1541,"<="&I8,FreightRates!$E$2:$E$1541,">="&I8) -> 0
A9: =OrderList!A9 -> 1.447158e+09 | B9: =OrderList!C9 -> PORT09 | C9: =OrderList!D9 -> V44_3 | D9: =OrderList!F9 -> CRF | E9: =OrderList!L9 -> PORT09 | F9: =OrderList!K9 -> PLANT16 | G9: =OrderList!J9 -> 1700106 | H9: =OrderList!M9 -> 427 | I9: =OrderList!N9 -> 2.86 | O9: =COUNTIF(FreightRates!$A$2:$A$1541,C9) -> 0 | Q9: =COUNTIFS(FreightRates!$A$2:$A$1541,C9,FreightRates!$B$2:$B$1541,B9,FreightRates!$C$2:$C$1541,E9) -> 0 | T9: =COUNTIFS(FreightRates!$A$2:$A$1541,C9,FreightRates!$B$2:$B$1541,B9,FreightRates!$C$2:$C$1541,E9,FreightRates!$F$2:$F$1541,D9,FreightRates!$D$2:$D$1541,"<="&I9,FreightRates!$E$2:$E$1541,">="&I9) -> 0
A10: =OrderList!A10 -> 1.4472193e+09 | B10: =OrderList!C10 -> PORT09 | C10: =OrderList!D10 -> V44_3 | D10: =OrderList!F10 -> CRF | E10: =OrderList!L10 -> PORT09 | F10: =OrderList!K10 -> PLANT16 | G10: =OrderList!J10 -> 1700106 | H10: =OrderList!M10 -> 1291 | I10: =OrderList!N10 -> 26.6 | O10: =COUNTIF(FreightRates!$A$2:$A$1541,C10) -> 0 | Q10: =COUNTIFS(FreightRates!$A$2:$A$1541,C10,FreightRates!$B$2:$B$1541,B10,FreightRates!$C$2:$C$1541,E10) -> 0 | T10: =COUNTIFS(FreightRates!$A$2:$A$1541,C10,FreightRates!$B$2:$B$1541,B10,FreightRates!$C$2:$C$1541,E10,FreightRates!$F$2:$F$1541,D10,FreightRates!$D$2:$D$1541,"<="&I10,FreightRates!$E$2:$E$1541,">="&I10) -> 0
A11: =OrderList!A11 -> 1.4473984e+09 | B11: =OrderList!C11 -> PORT09 | C11: =OrderList!D11 -> V44_3 | D11: =OrderList!F11 -> CRF | E11: =OrderList!L11 -> PORT09 | F11: =OrderList!K11 -> PLANT16 | G11: =OrderList!J11 -> 1700106 | H11: =OrderList!M11 -> 2294 | I11: =OrderList!N11 -> 62.2 | O11: =COUNTIF(FreightRates!$A$2:$A$1541,C11) -> 0 | Q11: =COUNTIFS(FreightRates!$A$2:$A$1541,C11,FreightRates!$B$2:$B$1541,B11,FreightRates!$C$2:$C$1541,E11) -> 0 | T11: =COUNTIFS(FreightRates!$A$2:$A$1541,C11,FreightRates!$B$2:$B$1541,B11,FreightRates!$C$2:$C$1541,E11,FreightRates!$F$2:$F$1541,D11,FreightRates!$D$2:$D$1541,"<="&I11,FreightRates!$E$2:$E$1541,">="&I11) -> 0
A12: =OrderList!A12 -> 1.4473817e+09 | B12: =OrderList!C12 -> PORT09 | C12: =OrderList!D12 -> V44_3 | D12: =OrderList!F12 -> CRF | E12: =OrderList!L12 -> PORT09 | F12: =OrderList!K12 -> PLANT16 | G12: =OrderList!J12 -> 1700106 | H12: =OrderList!M12 -> 2766 | I12: =OrderList!N12 -> 75.5 | O12: =COUNTIF(FreightRates!$A$2:$A$1541,C12) -> 0 | Q12: =COUNTIFS(FreightRates!$A$2:$A$1541,C12,FreightRates!$B$2:$B$1541,B12,FreightRates!$C$2:$C$1541,E12) -> 0 | T12: =COUNTIFS(FreightRates!$A$2:$A$1541,C12,FreightRates!$B$2:$B$1541,B12,FreightRates!$C$2:$C$1541,E12,FreightRates!$F$2:$F$1541,D12,FreightRates!$D$2:$D$1541,"<="&I12,FreightRates!$E$2:$E$1541,">="&I12) -> 0
A13: =OrderList!A13 -> 1.4471708e+09 | B13: =OrderList!C13 -> PORT09 | C13: =OrderList!D13 -> V44_3 | D13: =OrderList!F13 -> CRF | E13: =OrderList!L13 -> PORT09 | F13: =OrderList!K13 -> PLANT16 | G13: =OrderList!J13 -> 1700106 | H13: =OrderList!M13 -> 798 | I13: =OrderList!N13 -> 14.3 | O13: =COUNTIF(FreightRates!$A$2:$A$1541,C13) -> 0 | Q13: =COUNTIFS(FreightRates!$A$2:$A$1541,C13,FreightRates!$B$2:$B$1541,B13,FreightRates!$C$2:$C$1541,E13) -> 0 | T13: =COUNTIFS(FreightRates!$A$2:$A$1541,C13,FreightRates!$B$2:$B$1541,B13,FreightRates!$C$2:$C$1541,E13,FreightRates!$F$2:$F$1541,D13,FreightRates!$D$2:$D$1541,"<="&I13,FreightRates!$E$2:$E$1541,">="&I13) -> 0
A14: =OrderList!A14 -> 1.4471551e+09 | B14: =OrderList!C14 -> PORT09 | C14: =OrderList!D14 -> V44_3 | D14: =OrderList!F14 -> CRF | E14: =OrderList!L14 -> PORT09 | F14: =OrderList!K14 -> PLANT16 | G14: =OrderList!J14 -> 1697884 | H14: =OrderList!M14 -> 739 | I14: =OrderList!N14 -> 73.9 | O14: =COUNTIF(FreightRates!$A$2:$A$1541,C14) -> 0 | Q14: =COUNTIFS(FreightRates!$A$2:$A$1541,C14,FreightRates!$B$2:$B$1541,B14,FreightRates!$C$2:$C$1541,E14) -> 0 | T14: =COUNTIFS(FreightRates!$A$2:$A$1541,C14,FreightRates!$B$2:$B$1541,B14,FreightRates!$C$2:$C$1541,E14,FreightRates!$F$2:$F$1541,D14,FreightRates!$D$2:$D$1541,"<="&I14,FreightRates!$E$2:$E$1541,">="&I14) -> 0
... A855: =OrderList!A855 -> 1.4473909e+09 | B855: =OrderList!C855 -> PORT05 | C855: =OrderList!D855 -> V44_3 | D855: =OrderList!F855 -> CRF | E855: =OrderList!L855 -> PORT09 | F855: =OrderList!K855 -> PLANT04 | G855: =OrderList!J855 -> 1684170 | H855: =OrderList!M855 -> 348 | I855: =OrderList!N855 -> 2.1011073 | O855: =COUNTIF(FreightRates!$A$2:$A$1541,C855) -> 0 | Q855: =COUNTIFS(FreightRates!$A$2:$A$1541,C855,FreightRates!$B$2:$B$1541,B855,FreightRates!$C$2:$C$1541,E855) -> 0 | T855: =COUNTIFS(FreightRates!$A$2:$A$1541,C855,FreightRates!$B$2:$B$1541,B855,FreightRates!$C$2:$C$1541,E855,FreightRates!$F$2:$F$1541,D855,FreightRates!$D$2:$D$1541,"<="&I855,FreightRates!$E$2:$E$1541,">="&I855) -> 0
A856: =OrderList!A856 -> 1.4473852e+09 | B856: =OrderList!C856 -> PORT09 | C856: =OrderList!D856 -> V444_0 | D856: =OrderList!F856 -> DTP | E856: =OrderList!L856 -> PORT09 | F856: =OrderList!K856 -> PLANT16 | G856: =OrderList!J856 -> 1692724 | H856: =OrderList!M856 -> 332 | I856: =OrderList!N856 -> 1.0231429 | O856: =COUNTIF(FreightRates!$A$2:$A$1541,C856) -> 39 | Q856: =COUNTIFS(FreightRates!$A$2:$A$1541,C856,FreightRates!$B$2:$B$1541,B856,FreightRates!$C$2:$C$1541,E856) -> 2 | T856: =COUNTIFS(FreightRates!$A$2:$A$1541,C856,FreightRates!$B$2:$B$1541,B856,FreightRates!$C$2:$C$1541,E856,FreightRates!$F$2:$F$1541,D856,FreightRates!$D$2:$D$1541,"<="&I856,FreightRates!$E$2:$E$1541,">="&I856) -> 1 | U856: =COUNTIF(T2:T9216,">0") -> 6991
A857: =OrderList!A857 -> 1.4473378e+09 | B857: =OrderList!C857 -> PORT09 | C857: =OrderList!D857 -> V444_0 | D857: =OrderList!F857 -> DTP | E857: =OrderList!L857 -> PORT09 | F857: =OrderList!K857 -> PLANT16 | G857: =OrderList!J857 -> 1692724 | H857: =OrderList!M857 -> 358 | I857: =OrderList!N857 -> 0.61388573 | O857: =COUNTIF(FreightRates!$A$2:$A$1541,C857) -> 39 | Q857: =COUNTIFS(FreightRates!$A$2:$A$1541,C857,FreightRates!$B$2:$B$1541,B857,FreightRates!$C$2:$C$1541,E857) -> 2 | T857: =COUNTIFS(FreightRates!$A$2:$A$1541,C857,FreightRates!$B$2:$B$1541,B857,FreightRates!$C$2:$C$1541,E857,FreightRates!$F$2:$F$1541,D857,FreightRates!$D$2:$D$1541,"<="&I857,FreightRates!$E$2:$E$1541,">="&I857) -> 1
A858: =OrderList!A858 -> 1.4474069e+09 | B858: =OrderList!C858 -> PORT09 | C858: =OrderList!D858 -> V444_0 | D858: =OrderList!F858 -> DTP | E858: =OrderList!L858 -> PORT09 | F858: =OrderList!K858 -> PLANT16 | G858: =OrderList!J858 -> 1692722 | H858: =OrderList!M858 -> 409 | I858: =OrderList!N858 -> 37.041956 | O858: =COUNTIF(FreightRates!$A$2:$A$1541,C858) -> 39 | Q858: =COUNTIFS(FreightRates!$A$2:$A$1541,C858,FreightRates!$B$2:$B$1541,B858,FreightRates!$C$2:$C$1541,E858) -> 2 | T858: =COUNTIFS(FreightRates!$A$2:$A$1541,C858,FreightRates!$B$2:$B$1541,B858,FreightRates!$C$2:$C$1541,E858,FreightRates!$F$2:$F$1541,D858,FreightRates!$D$2:$D$1541,"<="&I858,FreightRates!$E$2:$E$1541,">="&I858) -> 1
A859: =OrderList!A859 -> 1.4471542e+09 | B859: =OrderList!C859 -> PORT09 | C859: =OrderList!D859 -> V444_0 | D859: =OrderList!F859 -> DTP | E859: =OrderList!L859 -> PORT09 | F859: =OrderList!K859 -> PLANT16 | G859: =OrderList!J859 -> 1692722 | H859: =OrderList!M859 -> 438 | I859: =OrderList!N859 -> 42.830667 | O859: =COUNTIF(FreightRates!$A$2:$A$1541,C859) -> 39 | Q859: =COUNTIFS(FreightRates!$A$2:$A$1541,C859,FreightRates!$B$2:$B$1541,B859,FreightRates!$C$2:$C$1541,E859) -> 2 | T859: =COUNTIFS(FreightRates!$A$2:$A$1541,C859,FreightRates!$B$2:$B$1541,B859,FreightRates!$C$2:$C$1541,E859,FreightRates!$F$2:$F$1541,D859,FreightRates!$D$2:$D$1541,"<="&I859,FreightRates!$E$2:$E$1541,">="&I859) -> 1
A860: =OrderList!A860 -> 1.4471634e+09 | B860: =OrderList!C860 -> PORT09 | C860: =OrderList!D860 -> V444_0 | D860: =OrderList!F860 -> DTP | E860: =OrderList!L860 -> PORT09 | F860: =OrderList!K860 -> PLANT16 | G860: =OrderList!J860 -> 1692722 | H860: =OrderList!M860 -> 824 | I860: =OrderList!N860 -> 133.22427 | O860: =COUNTIF(FreightRates!$A$2:$A$1541,C860) -> 39 | Q860: =COUNTIFS(FreightRates!$A$2:$A$1541,C860,FreightRates!$B$2:$B$1541,B860,FreightRates!$C$2:$C$1541,E860) -> 2 | T860: =COUNTIFS(FreightRates!$A$2:$A$1541,C860,FreightRates!$B$2:$B$1541,B860,FreightRates!$C$2:$C$1541,E860,FreightRates!$F$2:$F$1541,D860,FreightRates!$D$2:$D$1541,"<="&I860,FreightRates!$E$2:$E$1541,">="&I860) -> 1
A861: =OrderList!A861 -> 1.4472137e+09 | B861: =OrderList!C861 -> PORT09 | C861: =OrderList!D861 -> V444_0 | D861: =OrderList!F861 -> DTP | E861: =OrderList!L861 -> PORT09 | F861: =OrderList!K861 -> PLANT16 | G861: =OrderList!J861 -> 1692722 | H861: =OrderList!M861 -> 378 | I861: =OrderList!N861 -> 20.309689 | O861: =COUNTIF(FreightRates!$A$2:$A$1541,C861) -> 39 | Q861: =COUNTIFS(FreightRates!$A$2:$A$1541,C861,FreightRates!$B$2:$B$1541,B861,FreightRates!$C$2:$C$1541,E861) -> 2 | T861: =COUNTIFS(FreightRates!$A$2:$A$1541,C861,FreightRates!$B$2:$B$1541,B861,FreightRates!$C$2:$C$1541,E861,FreightRates!$F$2:$F$1541,D861,FreightRates!$D$2:$D$1541,"<="&I861,FreightRates!$E$2:$E$1541,">="&I861) -> 1
A862: =OrderList!A862 -> 1.4471535e+09 | B862: =OrderList!C862 -> PORT09 | C862: =OrderList!D862 -> V444_0 | D862: =OrderList!F862 -> DTP | E862: =OrderList!L862 -> PORT09 | F862: =OrderList!K862 -> PLANT16 | G862: =OrderList!J862 -> 1692722 | H862: =OrderList!M862 -> 501 | I862: =OrderList!N862 -> 58.774223 | O862: =COUNTIF(FreightRates!$A$2:$A$1541,C862) -> 39 | Q862: =COUNTIFS(FreightRates!$A$2:$A$1541,C862,FreightRates!$B$2:$B$1541,B862,FreightRates!$C$2:$C$1541,E862) -> 2 | T862: =COUNTIFS(FreightRates!$A$2:$A$1541,C862,FreightRates!$B$2:$B$1541,B862,FreightRates!$C$2:$C$1541,E862,FreightRates!$F$2:$F$1541,D862,FreightRates!$D$2:$D$1541,"<="&I862,FreightRates!$E$2:$E$1541,">="&I862) -> 1
A863: =OrderList!A863 -> 1.4473687e+09 | B863: =OrderList!C863 -> PORT09 | C863: =OrderList!D863 -> V444_0 | D863: =OrderList!F863 -> DTP | E863: =OrderList!L863 -> PORT09 | F863: =OrderList!K863 -> PLANT16 | G863: =OrderList!J863 -> 1692722 | H863: =OrderList!M863 -> 421 | I863: =OrderList!N863 -> 26.887112 | O863: =COUNTIF(FreightRates!$A$2:$A$1541,C863) -> 39 | Q863: =COUNTIFS(FreightRates!$A$2:$A$1541,C863,FreightRates!$B$2:$B$1541,B863,FreightRates!$C$2:$C$1541,E863) -> 2 | T863: =COUNTIFS(FreightRates!$A$2:$A$1541,C863,FreightRates!$B$2:$B$1541,B863,FreightRates!$C$2:$C$1541,E863,FreightRates!$F$2:$F$1541,D863,FreightRates!$D$2:$D$1541,"<="&I863,FreightRates!$E$2:$E$1541,">="&I863) -> 1
A864: =OrderList!A864 -> 1.4472137e+09 | B864: =OrderList!C864 -> PORT09 | C864: =OrderList!D864 -> V444_0 | D864: =OrderList!F864 -> DTP | E864: =OrderList!L864 -> PORT09 | F864: =OrderList!K864 -> PLANT16 | G864: =OrderList!J864 -> 1692722 | H864: =OrderList!M864 -> 288 | I864: =OrderList!N864 -> 11.154845 | O864: =COUNTIF(FreightRates!$A$2:$A$1541,C864) -> 39 | Q864: =COUNTIFS(FreightRates!$A$2:$A$1541,C864,FreightRates!$B$2:$B$1541,B864,FreightRates!$C$2:$C$1541,E864) -> 2 | T864: =COUNTIFS(FreightRates!$A$2:$A$1541,C864,FreightRates!$B$2:$B$1541,B864,FreightRates!$C$2:$C$1541,E864,FreightRates!$F$2:$F$1541,D864,FreightRates!$D$2:$D$1541,"<="&I864,FreightRates!$E$2:$E$1541,">="&I864) -> 1
A865: =OrderList!A865 -> 1.4472137e+09 | B865: =OrderList!C865 -> PORT09 | C865: =OrderList!D865 -> V444_0 | D865: =OrderList!F865 -> DTP | E865: =OrderList!L865 -> PORT09 | F865: =OrderList!K865 -> PLANT16 | G865: =OrderList!J865 -> 1692722 | H865: =OrderList!M865 -> 322 | I865: =OrderList!N865 -> 22.309689 | O865: =COUNTIF(FreightRates!$A$2:$A$1541,C865) -> 39 | Q865: =COUNTIFS(FreightRates!$A$2:$A$1541,C865,FreightRates!$B$2:$B$1541,B865,FreightRates!$C$2:$C$1541,E865) -> 2 | T865: =COUNTIFS(FreightRates!$A$2:$A$1541,C865,FreightRates!$B$2:$B$1541,B865,FreightRates!$C$2:$C$1541,E865,FreightRates!$F$2:$F$1541,D865,FreightRates!$D$2:$D$1541,"<="&I865,FreightRates!$E$2:$E$1541,">="&I865) -> 1
A866: =OrderList!A866 -> 1.4471571e+09 | B866: =OrderList!C866 -> PORT09 | C866: =OrderList!D866 -> V444_0 | D866: =OrderList!F866 -> DTP | E866: =OrderList!L866 -> PORT09 | F866: =OrderList!K866 -> PLANT16 | G866: =OrderList!J866 -> 1692737 | H866: =OrderList!M866 -> 303 | I866: =OrderList!N866 -> 11.66246 | O866: =COUNTIF(FreightRates!$A$2:$A$1541,C866) -> 39 | Q866: =COUNTIFS(FreightRates!$A$2:$A$1541,C866,FreightRates!$B$2:$B$1541,B866,FreightRates!$C$2:$C$1541,E866) -> 2 | T866: =COUNTIFS(FreightRates!$A$2:$A$1541,C866,FreightRates!$B$2:$B$1541,B866,FreightRates!$C$2:$C$1541,E866,FreightRates!$F$2:$F$1541,D866,FreightRates!$D$2:$D$1541,"<="&I866,FreightRates!$E$2:$E$1541,">="&I866) -> 1
A867: =OrderList!A867 -> 1.4472178e+09 | B867: =OrderList!C867 -> PORT09 | C867: =OrderList!D867 -> V444_0 | D867: =OrderList!F867 -> DTP | E867: =OrderList!L867 -> PORT09 | F867: =OrderList!K867 -> PLANT16 | G867: =OrderList!J867 -> 1692737 | H867: =OrderList!M867 -> 409 | I867: =OrderList!N867 -> 37.987381 | O867: =COUNTIF(FreightRates!$A$2:$A$1541,C867) -> 39 | Q867: =COUNTIFS(FreightRates!$A$2:$A$1541,C867,FreightRates!$B$2:$B$1541,B867,FreightRates!$C$2:$C$1541,E867) -> 2 | T867: =COUNTIFS(FreightRates!$A$2:$A$1541,C867,FreightRates!$B$2:$B$1541,B867,FreightRates!$C$2:$C$1541,E867,FreightRates!$F$2:$F$1541,D867,FreightRates!$D$2:$D$1541,"<="&I867,FreightRates!$E$2:$E$1541,">="&I867) -> 1
A868: =OrderList!A868 -> 1.4471571e+09 | B868: =OrderList!C868 -> PORT09 | C868: =OrderList!D868 -> V444_0 | D868: =OrderList!F868 -> DTP | E868: =OrderList!L868 -> PORT09 | F868: =OrderList!K868 -> PLANT16 | G868: =OrderList!J868 -> 1692723 | H868: =OrderList!M868 -> 334 | I868: =OrderList!N868 -> 1.6546574 | O868: =COUNTIF(FreightRates!$A$2:$A$1541,C868) -> 39 | Q868: =COUNTIFS(FreightRates!$A$2:$A$1541,C868,FreightRates!$B$2:$B$1541,B868,FreightRates!$C$2:$C$1541,E868) -> 2 | T868: =COUNTIFS(FreightRates!$A$2:$A$1541,C868,FreightRates!$B$2:$B$1541,B868,FreightRates!$C$2:$C$1541,E868,FreightRates!$F$2:$F$1541,D868,FreightRates!$D$2:$D$1541,"<="&I868,FreightRates!$E$2:$E$1541,">="&I868) -> 1
... A1709: =OrderList!A1709 -> 1.447312e+09 | B1709: =OrderList!C1709 -> PORT04 | C1709: =OrderList!D1709 -> V444_0 | D1709: =OrderList!F1709 -> DTP | E1709: =OrderList!L1709 -> PORT09 | F1709: =OrderList!K1709 -> PLANT03 | G1709: =OrderList!J1709 -> 1688288 | H1709: =OrderList!M1709 -> 278 | I1709: =OrderList!N1709 -> 0.85281726 | O1709: =COUNTIF(FreightRates!$A$2:$A$1541,C1709) -> 39 | Q1709: =COUNTIFS(FreightRates!$A$2:$A$1541,C1709,FreightRates!$B$2:$B$1541,B1709,FreightRates!$C$2:$C$1541,E1709) -> 20 | T1709: =COUNTIFS(FreightRates!$A$2:$A$1541,C1709,FreightRates!$B$2:$B$1541,B1709,FreightRates!$C$2:$C$1541,E1709,FreightRates!$F$2:$F$1541,D1709,FreightRates!$D$2:$D$1541,"<="&I1709,FreightRates!$E$2:$E$1541,">="&I1709) -> 2
A1710: =OrderList!A1710 -> 1.447373e+09 | B1710: =OrderList!C1710 -> PORT04 | C1710: =OrderList!D1710 -> V444_0 | D1710: =OrderList!F1710 -> DTP | E1710: =OrderList!L1710 -> PORT09 | F1710: =OrderList!K1710 -> PLANT03 | G1710: =OrderList!J1710 -> 1688288 | H1710: =OrderList!M1710 -> 276 | I1710: =OrderList!N1710 -> 1.7056345 | O1710: =COUNTIF(FreightRates!$A$2:$A$1541,C1710) -> 39 | Q1710: =COUNTIFS(FreightRates!$A$2:$A$1541,C1710,FreightRates!$B$2:$B$1541,B1710,FreightRates!$C$2:$C$1541,E1710) -> 20 | T1710: =COUNTIFS(FreightRates!$A$2:$A$1541,C1710,FreightRates!$B$2:$B$1541,B1710,FreightRates!$C$2:$C$1541,E1710,FreightRates!$F$2:$F$1541,D1710,FreightRates!$D$2:$D$1541,"<="&I1710,FreightRates!$E$2:$E$1541,">="&I1710) -> 2 | U1710: =COUNTIF(T2:T9216,">0") -> 6991 | V1710: =COUNTIFS(FreightRates!$A$2:$A$1541,C1710,FreightRates!$B$2:$B$1541,B1710,FreightRates!$C$2:$C$1541,E1710) -> 20 | W1710: =COUNTIFS(FreightRates!$A$2:$A$1541,C1710,FreightRates!$B$2:$B$1541,B1710,FreightRates!$C$2:$C$1541,E1710,FreightRates!$F$2:$F$1541,D1710) -> 10 | X1710: =COUNTIFS(FreightRates!$A$2:$A$1541,C1710,FreightRates!$B$2:$B$1541,B1710,FreightRates!$C$2:$C$1541,E1710,FreightRates!$F$2:$F$1541,D1710,FreightRates!$D$2:$D$1541,"<="&I1710,FreightRates!$E$2:$E$1541,">="&I1710) -> 2
A1711: =OrderList!A1711 -> 1.4473219e+09 | B1711: =OrderList!C1711 -> PORT04 | C1711: =OrderList!D1711 -> V444_0 | D1711: =OrderList!F1711 -> DTP | E1711: =OrderList!L1711 -> PORT09 | F1711: =OrderList!K1711 -> PLANT03 | G1711: =OrderList!J1711 -> 1688288 | H1711: =OrderList!M1711 -> 284 | I1711: =OrderList!N1711 -> 1.7056345 | O1711: =COUNTIF(FreightRates!$A$2:$A$1541,C1711) -> 39 | Q1711: =COUNTIFS(FreightRates!$A$2:$A$1541,C1711,FreightRates!$B$2:$B$1541,B1711,FreightRates!$C$2:$C$1541,E1711) -> 20 | T1711: =COUNTIFS(FreightRates!$A$2:$A$1541,C1711,FreightRates!$B$2:$B$1541,B1711,FreightRates!$C$2:$C$1541,E1711,FreightRates!$F$2:$F$1541,D1711,FreightRates!$D$2:$D$1541,"<="&I1711,FreightRates!$E$2:$E$1541,">="&I1711) -> 2
A1712: =OrderList!A1712 -> 1.4473296e+09 | B1712: =OrderList!C1712 -> PORT04 | C1712: =OrderList!D1712 -> V444_0 | D1712: =OrderList!F1712 -> DTP | E1712: =OrderList!L1712 -> PORT09 | F1712: =OrderList!K1712 -> PLANT03 | G1712: =OrderList!J1712 -> 1688288 | H1712: =OrderList!M1712 -> 277 | I1712: =OrderList!N1712 -> 0.42640863 | O1712: =COUNTIF(FreightRates!$A$2:$A$1541,C1712) -> 39 | Q1712: =COUNTIFS(FreightRates!$A$2:$A$1541,C1712,FreightRates!$B$2:$B$1541,B1712,FreightRates!$C$2:$C$1541,E1712) -> 20 | T1712: =COUNTIFS(FreightRates!$A$2:$A$1541,C1712,FreightRates!$B$2:$B$1541,B1712,FreightRates!$C$2:$C$1541,E1712,FreightRates!$F$2:$F$1541,D1712,FreightRates!$D$2:$D$1541,"<="&I1712,FreightRates!$E$2:$E$1541,">="&I1712) -> 2
A1713: =OrderList!A1713 -> 1.4473855e+09 | B1713: =OrderList!C1713 -> PORT04 | C1713: =OrderList!D1713 -> V444_0 | D1713: =OrderList!F1713 -> DTP | E1713: =OrderList!L1713 -> PORT09 | F1713: =OrderList!K1713 -> PLANT03 | G1713: =OrderList!J1713 -> 1688288 | H1713: =OrderList!M1713 -> 286 | I1713: =OrderList!N1713 -> 0.21320432 | O1713: =COUNTIF(FreightRates!$A$2:$A$1541,C1713) -> 39 | Q1713: =COUNTIFS(FreightRates!$A$2:$A$1541,C1713,FreightRates!$B$2:$B$1541,B1713,FreightRates!$C$2:$C$1541,E1713) -> 20 | T1713: =COUNTIFS(FreightRates!$A$2:$A$1541,C1713,FreightRates!$B$2:$B$1541,B1713,FreightRates!$C$2:$C$1541,E1713,FreightRates!$F$2:$F$1541,D1713,FreightRates!$D$2:$D$1541,"<="&I1713,FreightRates!$E$2:$E$1541,">="&I1713) -> 2
A1714: =OrderList!A1714 -> 1.4472218e+09 | B1714: =OrderList!C1714 -> PORT04 | C1714: =OrderList!D1714 -> V444_0 | D1714: =OrderList!F1714 -> DTP | E1714: =OrderList!L1714 -> PORT09 | F1714: =OrderList!K1714 -> PLANT03 | G1714: =OrderList!J1714 -> 1688288 | H1714: =OrderList!M1714 -> 387 | I1714: =OrderList!N1714 -> 6.8225381 | O1714: =COUNTIF(FreightRates!$A$2:$A$1541,C1714) -> 39 | Q1714: =COUNTIFS(FreightRates!$A$2:$A$1541,C1714,FreightRates!$B$2:$B$1541,B1714,FreightRates!$C$2:$C$1541,E1714) -> 20 | T1714: =COUNTIFS(FreightRates!$A$2:$A$1541,C1714,FreightRates!$B$2:$B$1541,B1714,FreightRates!$C$2:$C$1541,E1714,FreightRates!$F$2:$F$1541,D1714,FreightRates!$D$2:$D$1541,"<="&I1714,FreightRates!$E$2:$E$1541,">="&I1714) -> 2
A1715: =OrderList!A1715 -> 1.4473869e+09 | B1715: =OrderList!C1715 -> PORT04 | C1715: =OrderList!D1715 -> V444_0 | D1715: =OrderList!F1715 -> DTP | E1715: =OrderList!L1715 -> PORT09 | F1715: =OrderList!K1715 -> PLANT03 | G1715: =OrderList!J1715 -> 1688288 | H1715: =OrderList!M1715 -> 275 | I1715: =OrderList!N1715 -> 1.8122367 | O1715: =COUNTIF(FreightRates!$A$2:$A$1541,C1715) -> 39 | Q1715: =COUNTIFS(FreightRates!$A$2:$A$1541,C1715,FreightRates!$B$2:$B$1541,B1715,FreightRates!$C$2:$C$1541,E1715) -> 20 | T1715: =COUNTIFS(FreightRates!$A$2:$A$1541,C1715,FreightRates!$B$2:$B$1541,B1715,FreightRates!$C$2:$C$1541,E1715,FreightRates!$F$2:$F$1541,D1715,FreightRates!$D$2:$D$1541,"<="&I1715,FreightRates!$E$2:$E$1541,">="&I1715) -> 2
A1716: =OrderList!A1716 -> 1.4471844e+09 | B1716: =OrderList!C1716 -> PORT04 | C1716: =OrderList!D1716 -> V444_0 | D1716: =OrderList!F1716 -> DTP | E1716: =OrderList!L1716 -> PORT09 | F1716: =OrderList!K1716 -> PLANT03 | G1716: =OrderList!J1716 -> 1688288 | H1716: =OrderList!M1716 -> 290 | I1716: =OrderList!N1716 -> 3.4112691 | O1716: =COUNTIF(FreightRates!$A$2:$A$1541,C1716) -> 39 | Q1716: =COUNTIFS(FreightRates!$A$2:$A$1541,C1716,FreightRates!$B$2:$B$1541,B1716,FreightRates!$C$2:$C$1541,E1716) -> 20 | T1716: =COUNTIFS(FreightRates!$A$2:$A$1541,C1716,FreightRates!$B$2:$B$1541,B1716,FreightRates!$C$2:$C$1541,E1716,FreightRates!$F$2:$F$1541,D1716,FreightRates!$D$2:$D$1541,"<="&I1716,FreightRates!$E$2:$E$1541,">="&I1716) -> 2
A1717: =OrderList!A1717 -> 1.4473943e+09 | B1717: =OrderList!C1717 -> PORT04 | C1717: =OrderList!D1717 -> V444_0 | D1717: =OrderList!F1717 -> DTP | E1717: =OrderList!L1717 -> PORT09 | F1717: =OrderList!K1717 -> PLANT03 | G1717: =OrderList!J1717 -> 1688288 | H1717: =OrderList!M1717 -> 294 | I1717: =OrderList!N1717 -> 1.0660216 | O1717: =COUNTIF(FreightRates!$A$2:$A$1541,C1717) -> 39 | Q1717: =COUNTIFS(FreightRates!$A$2:$A$1541,C1717,FreightRates!$B$2:$B$1541,B1717,FreightRates!$C$2:$C$1541,E1717) -> 20 | T1717: =COUNTIFS(FreightRates!$A$2:$A$1541,C1717,FreightRates!$B$2:$B$1541,B1717,FreightRates!$C$2:$C$1541,E1717,FreightRates!$F$2:$F$1541,D1717,FreightRates!$D$2:$D$1541,"<="&I1717,FreightRates!$E$2:$E$1541,">="&I1717) -> 2
A1718: =OrderList!A1718 -> 1.4473261e+09 | B1718: =OrderList!C1718 -> PORT04 | C1718: =OrderList!D1718 -> V444_0 | D1718: =OrderList!F1718 -> DTP | E1718: =OrderList!L1718 -> PORT09 | F1718: =OrderList!K1718 -> PLANT03 | G1718: =OrderList!J1718 -> 1688288 | H1718: =OrderList!M1718 -> 265 | I1718: =OrderList!N1718 -> 0.42640863 | O1718: =COUNTIF(FreightRates!$A$2:$A$1541,C1718) -> 39 | Q1718: =COUNTIFS(FreightRates!$A$2:$A$1541,C1718,FreightRates!$B$2:$B$1541,B1718,FreightRates!$C$2:$C$1541,E1718) -> 20 | T1718: =COUNTIFS(FreightRates!$A$2:$A$1541,C1718,FreightRates!$B$2:$B$1541,B1718,FreightRates!$C$2:$C$1541,E1718,FreightRates!$F$2:$F$1541,D1718,FreightRates!$D$2:$D$1541,"<="&I1718,FreightRates!$E$2:$E$1541,">="&I1718) -> 2
A1719: =OrderList!A1719 -> 1.4473084e+09 | B1719: =OrderList!C1719 -> PORT04 | C1719: =OrderList!D1719 -> V444_0 | D1719: =OrderList!F1719 -> DTP | E1719: =OrderList!L1719 -> PORT09 | F1719: =OrderList!K1719 -> PLANT03 | G1719: =OrderList!J1719 -> 1688288 | H1719: =OrderList!M1719 -> 366 | I1719: =OrderList!N1719 -> 7.6753554 | O1719: =COUNTIF(FreightRates!$A$2:$A$1541,C1719) -> 39 | Q1719: =COUNTIFS(FreightRates!$A$2:$A$1541,C1719,FreightRates!$B$2:$B$1541,B1719,FreightRates!$C$2:$C$1541,E1719) -> 20 | T1719: =COUNTIFS(FreightRates!$A$2:$A$1541,C1719,FreightRates!$B$2:$B$1541,B1719,FreightRates!$C$2:$C$1541,E1719,FreightRates!$F$2:$F$1541,D1719,FreightRates!$D$2:$D$1541,"<="&I1719,FreightRates!$E$2:$E$1541,">="&I1719) -> 2
A1720: =OrderList!A1720 -> 1.447292e+09 | B1720: =OrderList!C1720 -> PORT04 | C1720: =OrderList!D1720 -> V444_0 | D1720: =OrderList!F1720 -> DTP | E1720: =OrderList!L1720 -> PORT09 | F1720: =OrderList!K1720 -> PLANT03 | G1720: =OrderList!J1720 -> 1688288 | H1720: =OrderList!M1720 -> 269 | I1720: =OrderList!N1720 -> 0.10660216 | O1720: =COUNTIF(FreightRates!$A$2:$A$1541,C1720) -> 39 | Q1720: =COUNTIFS(FreightRates!$A$2:$A$1541,C1720,FreightRates!$B$2:$B$1541,B1720,FreightRates!$C$2:$C$1541,E1720) -> 20 | T1720: =COUNTIFS(FreightRates!$A$2:$A$1541,C1720,FreightRates!$B$2:$B$1541,B1720,FreightRates!$C$2:$C$1541,E1720,FreightRates!$F$2:$F$1541,D1720,FreightRates!$D$2:$D$1541,"<="&I1720,FreightRates!$E$2:$E$1541,">="&I1720) -> 2
...

Sheet Dashboard_Data
A1: Metric | B1: Value
A2: Total Orders | B2: =COUNTA(OrderList!A2:A9216) -> 9215
A3: Total Quantity | B3: =SUM(OrderList!M2:M9216) -> 29513315
A4: Unique Products | B4: =COUNTA(Order_Analysis!J6:J777) -> 772
A5: Plants in Network | B5: =COUNTA(Capacity_Analysis!A2:A20) -> 19
A6: Products with One Supplying Plant | B6: =Order_Analysis!N6 -> 503

Sheet WhCosts
A1: WH | B1: Cost/unit
A2: PLANT15 | B2: 1.4150634
A3: PLANT17 | B3: 0.42894659
A4: PLANT18 | B4: 2.0362538
A5: PLANT05 | B5: 0.48814438
A6: PLANT02 | B6: 0.47750352
A7: PLANT01 | B7: 0.56697618
A8: PLANT06 | B8: 0.5540881
A9: PLANT10 | B9: 0.4935819
A10: PLANT07 | B10: 0.37142394
A11: PLANT14 | B11: 0.63432974
A12: PLANT16 | B12: 1.9198075
A13: PLANT12 | B13: 0.77313179
... A20: PLANT04 | B20: 0.4285033

Sheet WhCapacities
A1: Plant ID | B1: Daily Capacity
A2: PLANT15 | B2: 11
A3: PLANT17 | B3: 8
A4: PLANT18 | B4: 111
A5: PLANT05 | B5: 385
A6: PLANT02 | B6: 138
A7: PLANT01 | B7: 1070
A8: PLANT06 | B8: 49
A9: PLANT10 | B9: 118
A10: PLANT07 | B10: 265
A11: PLANT14 | B11: 549
A12: PLANT16 | B12: 457
A13: PLANT12 | B13: 209
... A20: PLANT04 | B20: 554

Sheet ProductsPerPlant
A1: Plant Code | B1: Product ID
A2: PLANT15 | B2: 1698815
A3: PLANT17 | B3: 1664419
A4: PLANT17 | B4: 1664426
A5: PLANT17 | B5: 1672826
A6: PLANT17 | B6: 1674916
A7: PLANT17 | B7: 1674918
A8: PLANT17 | B8: 1675507
A9: PLANT17 | B9: 1676151
A10: PLANT17 | B10: 1676152
A11: PLANT17 | B11: 1677864
A12: PLANT17 | B12: 1677865
A13: PLANT17 | B13: 1679124
... A2037: PLANT04 | B2037: 1699974

Sheet PP_Duplicate_Check
A1: Plant Code | B1: Product ID
A2: PLANT15 | B2: 1698815
A3: PLANT17 | B3: 1664419
A4: PLANT17 | B4: 1664426
A5: PLANT17 | B5: 1672826
A6: PLANT17 | B6: 1674916
A7: PLANT17 | B7: 1674918
A8: PLANT17 | B8: 1675507
A9: PLANT17 | B9: 1676151
A10: PLANT17 | B10: 1676152
A11: PLANT17 | B11: 1677864
A12: PLANT17 | B12: 1677865
A13: PLANT17 | B13: 1679124
... A2037: PLANT04 | B2037: 1699974

Sheet VmiCustomers
A1: Plant Code | B1: Customers
A2: PLANT02 | B2: V5555555555555_16
A3: PLANT02 | B3: V555555555555555_29
A4: PLANT02 | B4: V555555555_3
A5: PLANT02 | B5: V55555555555555_8
A6: PLANT02 | B6: V55555555_9
A7: PLANT02 | B7: V55555_10
A8: PLANT02 | B8: V55555555_5
A9: PLANT06 | B9: V555555555555555_18
A10: PLANT06 | B10: V55555_10
A11: PLANT10 | B11: V555555555555555_29
A12: PLANT10 | B12: V555555_34
... A15: PLANT11 | B15: V5555555555555555555_54

Sheet PlantPorts
A1: Plant Code | B1: Port
A2: PLANT01 | B2: PORT01
A3: PLANT01 | B3: PORT02
A4: PLANT02 | B4: PORT03
A5: PLANT03 | B5: PORT04
A6: PLANT04 | B6: PORT05
A7: PLANT05 | B7: PORT06
A8: PLANT06 | B8: PORT06
A9: PLANT07 | B9: PORT01
A10: PLANT07 | B10: PORT02
A11: PLANT08 | B11: PORT04
A12: PLANT09 | B12: PORT04
... A23: PLANT19 | B23: PORT04

Sheet Network_Analysis
A1: Count of Port | B1: Column Labels
A2: Row Labels | B2: PORT01 | C2: PORT02 | D2: PORT03 | E2: PORT04 | F2: PORT05 | G2: PORT06 | H2: PORT07 | I2: PORT08 | J2: PORT09 | K2: PORT10 | L2: PORT11 | M2: Grand Total
A3: PLANT01 | B3: 1 | C3: 1 | M3: 2
A4: PLANT02 | D4: 1 | M4: 1
A5: PLANT03 | E5: 1 | M5: 1
A6: PLANT04 | F6: 1 | M6: 1
A7: PLANT05 | G7: 1 | M7: 1
A8: PLANT06 | G8: 1 | M8: 1
A9: PLANT07 | B9: 1 | C9: 1 | M9: 2
A10: PLANT08 | E10: 1 | M10: 1
A11: PLANT09 | E11: 1 | M11: 1
A12: PLANT10 | B12: 1 | C12: 1 | M12: 2
A13: PLANT11 | E13: 1 | M13: 1
A14: PLANT12 | E14: 1 | M14: 1
A15: PLANT13 | E15: 1 | M15: 1
A16: PLANT14 | H16: 1 | M16: 1
A17: PLANT15 | I17: 1 | M17: 1
A18: PLANT16 | J18: 1 | M18: 1
A19: PLANT17 | K19: 1 | M19: 1
A20: PLANT18 | L20: 1 | M20: 1
A21: PLANT19 | E21: 1 | M21: 1
A22: Grand Total | B22: 3 | C22: 3 | D22: 1 | E22: 7 | F22: 1 | G22: 2 | H22: 1 | I22: 1 | J22: 1 | K22: 1 | L22: 1 | M22: 22
